Workbook

Sheet FC Jul 2026 - Sistema
G1: =SUM(G3:G928) -> 252026570
A2: SKU | B2: Descripcion | C2: Marca | D2: Categoria | E2: Jul_Sistema | F2: Precio_Bruto | G2: Jul_Excel | H2: Diferencia
A3: R3015 | B3: Lámpara Luminoterapia | C3: Acqui | D3: Salud y Bienestar | E3: 0 | F3: 34990 | G3: =F3*E3 -> 0 | H3: =E3-G3 -> 0 | I3: =_xlfn.XLOOKUP(A3,'[1]Forecast 2026'!$A:$A,'[1]Forecast 2026'!$AJ:$AJ,"NA",0,1) -> 0 | J3: =IFERROR(E3-I3,"") -> 0 | K3: =F3*H3 -> 0
A4: R3086 | B4: Calentador de Pies | C4: Acqui | D4: Dormitorio | E4: 512 | F4: 24990 | G4: =F4*E4 -> 12794880 | H4: =E4-G4 -> -12794368 | I4: =_xlfn.XLOOKUP(A4,'[1]Forecast 2026'!$A:$A,'[1]Forecast 2026'!$AJ:$AJ,"NA",0,1) -> 512 | J4: =IFERROR(E4-I4,"") -> 0
A5: R6359 | B5: Calientacamas 1 Plaza 100% Polyester Análogo | C5: Acqui | D5: Dormitorio | E5: 0 | F5: 19990 | G5: =F5*E5 -> 0 | H5: =E5-G5 -> 0 | I5: =_xlfn.XLOOKUP(A5,'[1]Forecast 2026'!$A:$A,'[1]Forecast 2026'!$AJ:$AJ,"NA",0,1) -> 0 | J5: =IFERROR(E5-I5,"") -> 0
A6: R6360 | B6: Calientacamas 2 Plazas 100% Polyester Análogo | C6: Acqui | D6: Dormitorio | E6: 0 | F6: 34990 | G6: =F6*E6 -> 0 | H6: =E6-G6 -> 0 | I6: =_xlfn.XLOOKUP(A6,'[1]Forecast 2026'!$A:$A,'[1]Forecast 2026'!$AJ:$AJ,"NA",0,1) -> 0 | J6: =IFERROR(E6-I6,"") -> 0
A7: R6361 | B7: Calientacamas 1 Plaza 100% Polyester Digital | C7: Acqui | D7: Dormitorio | E7: 0 | F7: 24990 | G7: =F7*E7 -> 0 | H7: =E7-G7 -> 0 | I7: =_xlfn.XLOOKUP(A7,'[1]Forecast 2026'!$A:$A,'[1]Forecast 2026'!$AJ:$AJ,"NA",0,1) -> 0 | J7: =IFERROR(E7-I7,"") -> 0
A8: R6362 | B8: Calientacamas 2 Plazas 100% Polyester Digital | C8: Acqui | D8: Dormitorio | E8: 0 | F8: 42990 | G8: =F8*E8 -> 0 | H8: =E8-G8 -> 0 | I8: =_xlfn.XLOOKUP(A8,'[1]Forecast 2026'!$A:$A,'[1]Forecast 2026'!$AJ:$AJ,"NA",0,1) -> 0 | J8: =IFERROR(E8-I8,"") -> 0
A9: R6363 | B9: Manta Térmica Control Digital 180x30 Acqui | C9: Acqui | D9: Dormitorio | E9: 0 | F9: 44990 | G9: =F9*E9 -> 0 | H9: =E9-G9 -> 0 | I9: =_xlfn.XLOOKUP(A9,'[1]Forecast 2026'!$A:$A,'[1]Forecast 2026'!$AJ:$AJ,"NA",0,1) -> 0 | J9: =IFERROR(E9-I9,"") -> 0
A10: R6365 | B10: Almohadilla Eléctrica Térmica Acqui | C10: Acqui | D10: Dormitorio | E10: 30 | F10: 21990 | G10: =F10*E10 -> 659700 | H10: =E10-G10 -> -659670 | I10: =_xlfn.XLOOKUP(A10,'[1]Forecast 2026'!$A:$A,'[1]Forecast 2026'!$AJ:$AJ,"NA",0,1) -> 30 | J10: =IFERROR(E10-I10,"") -> 0
A11: R6790 | B11: Cojín Ortopédico Asiento Lumbar Antideslizante Color Negro | C11: Acqui | D11: Salud y Bienestar | E11: 12 | F11: 19980 | G11: =F11*E11 -> 239760 | H11: =E11-G11 -> -239748 | I11: =_xlfn.XLOOKUP(A11,'[1]Forecast 2026'!$A:$A,'[1]Forecast 2026'!$AJ:$AJ,"NA",0,1) -> 12 | J11: =IFERROR(E11-I11,"") -> 0
A12: R6792 | B12: Manta con Peso Single 8kg concilieador de sueño | C12: Acqui | D12: Dormitorio | E12: 0 | F12: 54990 | G12: =F12*E12 -> 0 | H12: =E12-G12 -> 0 | I12: =_xlfn.XLOOKUP(A12,'[1]Forecast 2026'!$A:$A,'[1]Forecast 2026'!$AJ:$AJ,"NA",0,1) -> 0 | J12: =IFERROR(E12-I12,"") -> 0
A13: R6793 | B13: Manta con Peso Queen 12kg concilieador de sueño | C13: Acqui | D13: Dormitorio | E13: 0 | F13: 59990 | G13: =F13*E13 -> 0 | H13: =E13-G13 -> 0 | I13: =_xlfn.XLOOKUP(A13,'[1]Forecast 2026'!$A:$A,'[1]Forecast 2026'!$AJ:$AJ,"NA",0,1) -> 0 | J13: =IFERROR(E13-I13,"") -> 0
A14: R6794 | B14: Manta con Peso Queen 15kg concilieador de sueño | C14: Acqui | D14: Dormitorio | E14: 0 | F14: 64990 | G14: =F14*E14 -> 0 | H14: =E14-G14 -> 0 | I14: =_xlfn.XLOOKUP(A14,'[1]Forecast 2026'!$A:$A,'[1]Forecast 2026'!$AJ:$AJ,"NA",0,1) -> 0 | J14: =IFERROR(E14-I14,"") -> 0
A15: R6811 | B15: Pack 2 Almohada Memory Cervical Ortopédica | C15: Acqui | D15: Dormitorio | E15: 15 | F15: 17990 | G15: =F15*E15 -> 269850 | H15: =E15-G15 -> -269835 | I15: =_xlfn.XLOOKUP(A15,'[1]Forecast 2026'!$A:$A,'[1]Forecast 2026'!$AJ:$AJ,"NA",0,1) -> 15 | J15: =IFERROR(E15-I15,"") -> 0
... A928: R6957 | B928: Base de Cama 90x190x30cm 1 plaza NOVA | C928: Vincenzi | D928: Dormitorio | E928: 14 | F928: 89990 | G928: =F928*E928 -> 1259860 | H928: =E928-G928 -> -1259846 | I928: =_xlfn.XLOOKUP(A928,'[1]Forecast 2026'!$A:$A,'[1]Forecast 2026'!$AJ:$AJ,"NA",0,1) -> 14 | J928: =IFERROR(E928-I928,"") -> 0
A929: TOTAL | E929: =SUM(E3:E928) -> 6603 | G929: =SUM(G3:G928) -> 252026570 | H929: =SUM(H3:H928) -> -252019967

Sheet Hoja1
B1: a | C1: Exel | D1: Sistema | E1: S
B2: R3015 | D2: =SUMIF('FC Jul 2026 - Sistema'!A:A,B2,'FC Jul 2026 - Sistema'!E:E) -> 0 | E2: =C2-D2 -> 0
B3: R3086 | C3: 512 | D3: =SUMIF('FC Jul 2026 - Sistema'!A:A,B3,'FC Jul 2026 - Sistema'!E:E) -> 512 | E3: =C3-D3 -> 0
B4: R3357 | D4: =SUMIF('FC Jul 2026 - Sistema'!A:A,B4,'FC Jul 2026 - Sistema'!E:E) -> 0 | E4: =C4-D4 -> 0
B5: R6359 | D5: =SUMIF('FC Jul 2026 - Sistema'!A:A,B5,'FC Jul 2026 - Sistema'!E:E) -> 0 | E5: =C5-D5 -> 0
B6: R6360 | D6: =SUMIF('FC Jul 2026 - Sistema'!A:A,B6,'FC Jul 2026 - Sistema'!E:E) -> 0 | E6: =C6-D6 -> 0
B7: R6361 | D7: =SUMIF('FC Jul 2026 - Sistema'!A:A,B7,'FC Jul 2026 - Sistema'!E:E) -> 0 | E7: =C7-D7 -> 0
B8: R6362 | D8: =SUMIF('FC Jul 2026 - Sistema'!A:A,B8,'FC Jul 2026 - Sistema'!E:E) -> 0 | E8: =C8-D8 -> 0
B9: R6363 | D9: =SUMIF('FC Jul 2026 - Sistema'!A:A,B9,'FC Jul 2026 - Sistema'!E:E) -> 0 | E9: =C9-D9 -> 0
B10: R6365 | C10: 30 | D10: =SUMIF('FC Jul 2026 - Sistema'!A:A,B10,'FC Jul 2026 - Sistema'!E:E) -> 30 | E10: =C10-D10 -> 0
B11: R6790 | C11: 12 | D11: =SUMIF('FC Jul 2026 - Sistema'!A:A,B11,'FC Jul 2026 - Sistema'!E:E) -> 12 | E11: =C11-D11 -> 0
B12: R6792 | D12: =SUMIF('FC Jul 2026 - Sistema'!A:A,B12,'FC Jul 2026 - Sistema'!E:E) -> 0 | E12: =C12-D12 -> 0
B13: R6793 | D13: =SUMIF('FC Jul 2026 - Sistema'!A:A,B13,'FC Jul 2026 - Sistema'!E:E) -> 0 | E13: =C13-D13 -> 0
B14: R6794 | D14: =SUMIF('FC Jul 2026 - Sistema'!A:A,B14,'FC Jul 2026 - Sistema'!E:E) -> 0 | E14: =C14-D14 -> 0
B15: R6809 | D15: =SUMIF('FC Jul 2026 - Sistema'!A:A,B15,'FC Jul 2026 - Sistema'!E:E) -> 0 | E15: =C15-D15 -> 0
B16: R6811 | C16: 15 | D16: =SUMIF('FC Jul 2026 - Sistema'!A:A,B16,'FC Jul 2026 - Sistema'!E:E) -> 15 | E16: =C16-D16 -> 0
B17: R1088 | C17: 3 | D17: =SUMIF('FC Jul 2026 - Sistema'!A:A,B17,'FC Jul 2026 - Sistema'!E:E) -> 3 | E17: =C17-D17 -> 0
B18: R1091 | C18: 9 | D18: =SUMIF('FC Jul 2026 - Sistema'!A:A,B18,'FC Jul 2026 - Sistema'!E:E) -> 9 | E18: =C18-D18 -> 0
B19: R1101 | D19: =SUMIF('FC Jul 2026 - Sistema'!A:A,B19,'FC Jul 2026 - Sistema'!E:E) -> 0 | E19: =C19-D19 -> 0
B20: R1116 | D20: =SUMIF('FC Jul 2026 - Sistema'!A:A,B20,'FC Jul 2026 - Sistema'!E:E) -> 0 | E20: =C20-D20 -> 0
B21: R2745 | C21: 40 | D21: =SUMIF('FC Jul 2026 - Sistema'!A:A,B21,'FC Jul 2026 - Sistema'!E:E) -> 40 | E21: =C21-D21 -> 0
B22: R3259 | D22: =SUMIF('FC Jul 2026 - Sistema'!A:A,B22,'FC Jul 2026 - Sistema'!E:E) -> 0 | E22: =C22-D22 -> 0
B23: R3568 | D23: =SUMIF('FC Jul 2026 - Sistema'!A:A,B23,'FC Jul 2026 - Sistema'!E:E) -> 0 | E23: =C23-D23 -> 0
B24: R4027 | D24: =SUMIF('FC Jul 2026 - Sistema'!A:A,B24,'FC Jul 2026 - Sistema'!E:E) -> 0 | E24: =C24-D24 -> 0
B25: R4028 | D25: =SUMIF('FC Jul 2026 - Sistema'!A:A,B25,'FC Jul 2026 - Sistema'!E:E) -> 0 | E25: =C25-D25 -> 0
B26: R4030 | D26: =SUMIF('FC Jul 2026 - Sistema'!A:A,B26,'FC Jul 2026 - Sistema'!E:E) -> 0 | E26: =C26-D26 -> 0
B27: R4040 | C27: 100 | D27: =SUMIF('FC Jul 2026 - Sistema'!A:A,B27,'FC Jul 2026 - Sistema'!E:E) -> 100 | E27: =C27-D27 -> 0
B28: R4188 | C28: 1 | D28: =SUMIF('FC Jul 2026 - Sistema'!A:A,B28,'FC Jul 2026 - Sistema'!E:E) -> 1 | E28: =C28-D28 -> 0
B29: R4189 | C29: 1 | D29: =SUMIF('FC Jul 2026 - Sistema'!A:A,B29,'FC Jul 2026 - Sistema'!E:E) -> 1 | E29: =C29-D29 -> 0
B30: R4190 | C30: 1 | D30: =SUMIF('FC Jul 2026 - Sistema'!A:A,B30,'FC Jul 2026 - Sistema'!E:E) -> 1 | E30: =C30-D30 -> 0
B31: R4191 | D31: =SUMIF('FC Jul 2026 - Sistema'!A:A,B31,'FC Jul 2026 - Sistema'!E:E) -> 0 | E31: =C31-D31 -> 0
B32: R4192 | C32: 1 | D32: =SUMIF('FC Jul 2026 - Sistema'!A:A,B32,'FC Jul 2026 - Sistema'!E:E) -> 1 | E32: =C32-D32 -> 0
B33: R5290 | C33: 1 | D33: =SUMIF('FC Jul 2026 - Sistema'!A:A,B33,'FC Jul 2026 - Sistema'!E:E) -> 1 | E33: =C33-D33 -> 0
B34: R5742 | D34: =SUMIF('FC Jul 2026 - Sistema'!A:A,B34,'FC Jul 2026 - Sistema'!E:E) -> 0 | E34: =C34-D34 -> 0
B35: R5794 | D35: =SUMIF('FC Jul 2026 - Sistema'!A:A,B35,'FC Jul 2026 - Sistema'!E:E) -> 0 | E35: =C35-D35 -> 0
B36: R5821 | D36: =SUMIF('FC Jul 2026 - Sistema'!A:A,B36,'FC Jul 2026 - Sistema'!E:E) -> 0 | E36: =C36-D36 -> 0
B37: R6023 | C37: 66 | D37: =SUMIF('FC Jul 2026 - Sistema'!A:A,B37,'FC Jul 2026 - Sistema'!E:E) -> 66 | E37: =C37-D37 -> 0
B38: R6391 | D38: =SUMIF('FC Jul 2026 - Sistema'!A:A,B38,'FC Jul 2026 - Sistema'!E:E) -> 0 | E38: =C38-D38 -> 0
B39: R6471 | D39: =SUMIF('FC Jul 2026 - Sistema'!A:A,B39,'FC Jul 2026 - Sistema'!E:E) -> 0 | E39: =C39-D39 -> 0
B40: R6564 | D40: =SUMIF('FC Jul 2026 - Sistema'!A:A,B40,'FC Jul 2026 - Sistema'!E:E) -> 0 | E40: =C40-D40 -> 0
...
